Traceback (most recent call last):
  File "/Users/joreilly/opt/anaconda3/lib/python3.9/site-packages/jupyter_cache/executors/utils.py", line 58, in single_nb_execution
    executenb(
  File "/Users/joreilly/opt/anaconda3/lib/python3.9/site-packages/nbclient/client.py", line 1305, in execute
    return NotebookClient(nb=nb, resources=resources, km=km, **kwargs).execute()
  File "/Users/joreilly/opt/anaconda3/lib/python3.9/site-packages/jupyter_core/utils/__init__.py", line 166, in wrapped
    return loop.run_until_complete(inner)
  File "/Users/joreilly/opt/anaconda3/lib/python3.9/asyncio/base_events.py", line 647, in run_until_complete
    return future.result()
  File "/Users/joreilly/opt/anaconda3/lib/python3.9/site-packages/nbclient/client.py", line 705, in async_execute
    await self.async_execute_cell(
  File "/Users/joreilly/opt/anaconda3/lib/python3.9/site-packages/nbclient/client.py", line 1058, in async_execute_cell
    await self._check_raise_for_error(cell, cell_index, exec_reply)
  File "/Users/joreilly/opt/anaconda3/lib/python3.9/site-packages/nbclient/client.py", line 914, in _check_raise_for_error
    raise CellExecutionError.from_cell_and_msg(cell, exec_reply_content)
nbclient.exceptions.CellExecutionError: An error occurred while executing the following cell:
------------------
weather['snow'] = (weather.Rainfall_mm > 0 and weather.Tmin < 0)
weather
------------------


[0;31m---------------------------------------------------------------------------[0m
[0;31mValueError[0m                                Traceback (most recent call last)
[0;32m/var/folders/q4/twg1yll54y142rc02m5wwbt40000gr/T/ipykernel_1186/1303008489.py[0m in [0;36m?[0;34m()[0m
[0;32m----> 1[0;31m [0mweather[0m[0;34m[[0m[0;34m'snow'[0m[0;34m][0m [0;34m=[0m [0;34m([0m[0mweather[0m[0;34m.[0m[0mRainfall_mm[0m [0;34m>[0m [0;36m0[0m [0;32mand[0m [0mweather[0m[0;34m.[0m[0mTmin[0m [0;34m<[0m [0;36m0[0m[0;34m)[0m[0;34m[0m[0;34m[0m[0m
[0m[1;32m      2[0m [0mweather[0m[0;34m[0m[0;34m[0m[0m

[0;32m~/opt/anaconda3/lib/python3.9/site-packages/pandas/core/generic.py[0m in [0;36m?[0;34m(self)[0m
[1;32m   1464[0m     [0;34m@[0m[0mfinal[0m[0;34m[0m[0;34m[0m[0m
[1;32m   1465[0m     [0;32mdef[0m [0m__nonzero__[0m[0;34m([0m[0mself[0m[0;34m)[0m [0;34m->[0m [0mNoReturn[0m[0;34m:[0m[0;34m[0m[0;34m[0m[0m
[0;32m-> 1466[0;31m         raise ValueError(
[0m[1;32m   1467[0m             [0;34mf"The truth value of a {type(self).__name__} is ambiguous. "[0m[0;34m[0m[0;34m[0m[0m
[1;32m   1468[0m             [0;34m"Use a.empty, a.bool(), a.item(), a.any() or a.all()."[0m[0;34m[0m[0;34m[0m[0m
[1;32m   1469[0m         )

[0;31mValueError[0m: The truth value of a Series is ambiguous. Use a.empty, a.bool(), a.item(), a.any() or a.all().

