Traceback (most recent call last):
  File "/Users/joreilly/opt/anaconda3/lib/python3.9/site-packages/jupyter_cache/executors/utils.py", line 58, in single_nb_execution
    executenb(
  File "/Users/joreilly/opt/anaconda3/lib/python3.9/site-packages/nbclient/client.py", line 1305, in execute
    return NotebookClient(nb=nb, resources=resources, km=km, **kwargs).execute()
  File "/Users/joreilly/opt/anaconda3/lib/python3.9/site-packages/jupyter_core/utils/__init__.py", line 166, in wrapped
    return loop.run_until_complete(inner)
  File "/Users/joreilly/opt/anaconda3/lib/python3.9/asyncio/base_events.py", line 647, in run_until_complete
    return future.result()
  File "/Users/joreilly/opt/anaconda3/lib/python3.9/site-packages/nbclient/client.py", line 705, in async_execute
    await self.async_execute_cell(
  File "/Users/joreilly/opt/anaconda3/lib/python3.9/site-packages/nbclient/client.py", line 1058, in async_execute_cell
    await self._check_raise_for_error(cell, cell_index, exec_reply)
  File "/Users/joreilly/opt/anaconda3/lib/python3.9/site-packages/nbclient/client.py", line 914, in _check_raise_for_error
    raise CellExecutionError.from_cell_and_msg(cell, exec_reply_content)
nbclient.exceptions.CellExecutionError: An error occurred while executing the following cell:
------------------
display(df.groupby(['Type', 'Colour']).size())
df.groupby(['Type', 'Colour']).size().columns
# as you can see, this spits out an error because 'Type' and 'Colour' are indices not columns
# the actual output displayed is a pandas series, not a dataframe

------------------


[0;31m---------------------------------------------------------------------------[0m
[0;31mAttributeError[0m                            Traceback (most recent call last)
[0;32m/var/folders/q4/twg1yll54y142rc02m5wwbt40000gr/T/ipykernel_4353/2378309076.py[0m in [0;36m?[0;34m()[0m
[0;32m----> 2[0;31m [0mdisplay[0m[0;34m([0m[0mdf[0m[0;34m.[0m[0mgroupby[0m[0;34m([0m[0;34m[[0m[0;34m'Type'[0m[0;34m,[0m [0;34m'Colour'[0m[0;34m][0m[0;34m)[0m[0;34m.[0m[0msize[0m[0;34m([0m[0;34m)[0m[0;34m)[0m[0;34m[0m[0;34m[0m[0m
[0m[1;32m      3[0m [0mdf[0m[0;34m.[0m[0mgroupby[0m[0;34m([0m[0;34m[[0m[0;34m'Type'[0m[0;34m,[0m [0;34m'Colour'[0m[0;34m][0m[0;34m)[0m[0;34m.[0m[0msize[0m[0;34m([0m[0;34m)[0m[0;34m.[0m[0mcolumns[0m[0;34m[0m[0;34m[0m[0m
[1;32m      4[0m [0;31m# as you can see, this spits out an error because 'Type' and 'Colour' are indices not columns[0m[0;34m[0m[0;34m[0m[0m
[1;32m      5[0m [0;31m# the actual output displayed is a pandas series, not a dataframe[0m[0;34m[0m[0;34m[0m[0m

[0;32m~/opt/anaconda3/lib/python3.9/site-packages/pandas/core/generic.py[0m in [0;36m?[0;34m(self, name)[0m
[1;32m   5985[0m             [0;32mand[0m [0mname[0m [0;32mnot[0m [0;32min[0m [0mself[0m[0;34m.[0m[0m_accessors[0m[0;34m[0m[0;34m[0m[0m
[1;32m   5986[0m             [0;32mand[0m [0mself[0m[0;34m.[0m[0m_info_axis[0m[0;34m.[0m[0m_can_hold_identifiers_and_holds_name[0m[0;34m([0m[0mname[0m[0;34m)[0m[0;34m[0m[0;34m[0m[0m
[1;32m   5987[0m         ):
[1;32m   5988[0m             [0;32mreturn[0m [0mself[0m[0;34m[[0m[0mname[0m[0;34m][0m[0;34m[0m[0;34m[0m[0m
[0;32m-> 5989[0;31m         [0;32mreturn[0m [0mobject[0m[0;34m.[0m[0m__getattribute__[0m[0;34m([0m[0mself[0m[0;34m,[0m [0mname[0m[0;34m)[0m[0;34m[0m[0;34m[0m[0m
[0m
[0;31mAttributeError[0m: 'Series' object has no attribute 'columns'

