Traceback (most recent call last):
  File "/Users/joreilly/opt/anaconda3/lib/python3.9/site-packages/jupyter_cache/executors/utils.py", line 58, in single_nb_execution
    executenb(
  File "/Users/joreilly/opt/anaconda3/lib/python3.9/site-packages/nbclient/client.py", line 1204, in execute
    return NotebookClient(nb=nb, resources=resources, km=km, **kwargs).execute()
  File "/Users/joreilly/opt/anaconda3/lib/python3.9/site-packages/nbclient/util.py", line 84, in wrapped
    return just_run(coro(*args, **kwargs))
  File "/Users/joreilly/opt/anaconda3/lib/python3.9/site-packages/nbclient/util.py", line 62, in just_run
    return loop.run_until_complete(coro)
  File "/Users/joreilly/opt/anaconda3/lib/python3.9/asyncio/base_events.py", line 647, in run_until_complete
    return future.result()
  File "/Users/joreilly/opt/anaconda3/lib/python3.9/site-packages/nbclient/client.py", line 663, in async_execute
    await self.async_execute_cell(
  File "/Users/joreilly/opt/anaconda3/lib/python3.9/site-packages/nbclient/client.py", line 965, in async_execute_cell
    await self._check_raise_for_error(cell, cell_index, exec_reply)
  File "/Users/joreilly/opt/anaconda3/lib/python3.9/site-packages/nbclient/client.py", line 862, in _check_raise_for_error
    raise CellExecutionError.from_cell_and_msg(cell, exec_reply_content)
nbclient.exceptions.CellExecutionError: An error occurred while executing the following cell:
------------------
nReps=1000
sampleSize=50
p = np.empty(nReps)

for i in range(nReps):
    sample = pop_rNonZero.sample(n=sampleSize)
    p[i] = stats.pearsonr(sample['Maths'], sample['French'], alternative='greater')
    
# How many of our 10000 samples had p<0.05?
np.mean(p<0.05)
------------------

[0;31m---------------------------------------------------------------------------[0m
[0;31mTypeError[0m                                 Traceback (most recent call last)
[0;31mTypeError[0m: float() argument must be a string or a number, not 'PearsonRResult'

The above exception was the direct cause of the following exception:

[0;31mValueError[0m                                Traceback (most recent call last)
Cell [0;32mIn[9], line 7[0m
[1;32m      5[0m [38;5;28;01mfor[39;00m i [38;5;129;01min[39;00m [38;5;28mrange[39m(nReps):
[1;32m      6[0m     sample [38;5;241m=[39m pop_rNonZero[38;5;241m.[39msample(n[38;5;241m=[39msampleSize)
[0;32m----> 7[0m     p[i] [38;5;241m=[39m stats[38;5;241m.[39mpearsonr(sample[[38;5;124m'[39m[38;5;124mMaths[39m[38;5;124m'[39m], sample[[38;5;124m'[39m[38;5;124mFrench[39m[38;5;124m'[39m], alternative[38;5;241m=[39m[38;5;124m'[39m[38;5;124mgreater[39m[38;5;124m'[39m)
[1;32m      9[0m [38;5;66;03m# How many of our 10000 samples had p<0.05?[39;00m
[1;32m     10[0m np[38;5;241m.[39mmean(p[38;5;241m<[39m[38;5;241m0.05[39m)

[0;31mValueError[0m: setting an array element with a sequence.
ValueError: setting an array element with a sequence.

